Workbook
Name Slicer_product_category: #N/A
Name Slicer_year: #N/A

Sheet Return Rate 2
A3: Row Labels | B3: Sum of returned | C3: Sum of final_order | D3: Sum of Return Rate
A4: Beauty | B4: 83 | C4: 472 | D4: 0.17584746
A5: Books | B5: 76 | C5: 446 | D5: 0.17040359
A6: Clothing | B6: 88 | C6: 507 | D6: 0.17357002
A7: Electronics | B7: 96 | C7: 474 | D7: 0.20253165
A8: Furniture | B8: 79 | C8: 465 | D8: 0.16989247
A9: Groceries | B9: 95 | C9: 471 | D9: 0.20169851
A10: Sports | B10: 95 | C10: 508 | D10: 0.18700787
A11: Grand Total | B11: 612 | C11: 3343 | D11: 0.1830691

Sheet Return Rate 2 (2)
A3: Row Labels | B3: Rata-rata Kepuasan | C3: Jumlah Rating
A4: Cancelled | B4: 2.9230769 | C4: 325
A5: Delivered | B5: 3.1306432 | C5: 2503
A6: Pending | B6: 3.0935673 | C6: 171
A7: Returned | B7: 2.4601449 | C7: 552
A8: Shipped | B8: 3.1617162 | C8: 303
A9: Grand Total | B9: 3.0179035 | C9: 3854

Sheet Nilai Retur
A1: order_status_clean | B1: Returned
A2: sales_flag | B2: Include
A4: Row Labels | B4: Sum of sales_amount
A5: Electronics | B5: 20029868
A6: Furniture | B6: 6970993.6
A7: Sports | B7: 3534929.9
A8: Clothing | B8: 873313.81
A9: Beauty | B9: 499254.57
A10: Books | B10: 340159.07
A11: Groceries | B11: 146963.62
A12: Grand Total | B12: 32395483

Sheet P6 Return
A3: Row Labels | B3: Sum of returned | C3: Sum of final_order | D3: Return Rate
A4: Electronics | B4: 96 | C4: 474 | D4: 0.20253165
A5: Groceries | B5: 95 | C5: 471 | D5: 0.20169851
A6: Sports | B6: 95 | C6: 508 | D6: 0.18700787
A7: Beauty | B7: 83 | C7: 472 | D7: 0.17584746
A8: Clothing | B8: 88 | C8: 507 | D8: 0.17357002
A9: Books | B9: 76 | C9: 446 | D9: 0.17040359
A10: Furniture | B10: 79 | C10: 465 | D10: 0.16989247
A11: Grand Total | B11: 612 | C11: 3343 | D11: 0.1830691

Sheet P6 Return (2)
A3: Row Labels | B3: Return Rate
A4: Electronics | B4: 0.20253165
A5: Groceries | B5: 0.20169851
A6: Sports | B6: 0.18700787
A7: Beauty | B7: 0.17584746
A8: Clothing | B8: 0.17357002
A9: Books | B9: 0.17040359
A10: Furniture | B10: 0.16989247
A11: Grand Total | B11: 0.1830691

Sheet Cleaned-retail-sales-dataset
A1: order_id | B1: order_date | C1: order_date_clean | D1: customer_id | E1: customer_name | F1: age | G1: age_clean | H1: gender | I1: gender (clean) | J1: region | K1: city | L1: product_category | M1: product_name | N1: quantity | O1: quantity_clean | P1: unit_price | Q1: discount_pct | R1: sales_amount | S1: profit | T1: profit_margin | U1: shipping_cost | V1: payment_method | W1: customer_satisfaction | X1: return_flag | Y1: order_status | Z1: order_status_clean | AA1: days_clean | AB1: days_to_ship | AC1: year | AD1: year_month | AE1: age_group | AF1: discount_band | AG1: sales_flag | AH1: returned | AI1: final_order | AJ1: cancelled | AK1: orders_count
A2: ORD-04199 | B2: 45656 | C2: 45656 | D2: CUST53723 | E2: Sunita Kumar | F2: 15 | G2: 15 | H2: Male | I2: Male | J2: North | K2: Chandigarh | L2: Beauty | M2: Face Cream | N2: 9 | O2: 9 | P2: 1820.1 | Q2: 0.28 | R2: 9661.83 | S2: 5675.66 | T2: 0.587 | U2: 46.9 | V2: EMI | W2: 2 | X2: TRUE | Y2: Returned | Z2: Returned | AA2: 3 | AB2: 3 | AC2: 2024 | AD2: 45627 | AE2: <18 | AF2: 21-30% | AG2: =IF(N2=999,"Exclude","Include") -> Include | AH2: =IF(Z2="Returned",1,0) -> 1 | AI2: =IF(OR(Z2="Delivered",Z2="Returned"),1,0) -> 1 | AJ2: =IF(Z2="Cancelled",1,0) -> 0 | AK2: =1 -> 1
A3: ORD-04200 | B3: 45656 | C3: 45656 | D3: CUST38440 | E3: Rohan Rao | F3: 22 | G3: 22 | H3: Other | I3: Other | J3: South | K3: Bangalore | L3: Furniture | M3: Sofa | N3: 6 | O3: 6 | P3: 5868.58 | Q3: 0.29 | R3: 27272.26 | S3: 8506.96 | T3: 0.312 | U3: 61.17 | V3: Cash on Delivery | W3: 3 | X3: TRUE | Y3: Returned | Z3: Returned | AA3: 5 | AB3: 5 | AC3: 2024 | AD3: 45627 | AE3: 18-25 | AF3: 21-30% | AG3: =IF(N3=999,"Exclude","Include") -> Include | AH3: =IF(Z3="Returned",1,0) -> 1 | AI3: =IF(OR(Z3="Delivered",Z3="Returned"),1,0) -> 1 | AJ3: =IF(Z3="Cancelled",1,0) -> 0 | AK3: =1 -> 1
A4: ORD-04198 | B4: 45655 | C4: 45655 | D4: CUST54617 | E4: Kavya Joshi | F4: 36 | G4: 36 | H4: Other | I4: Other | J4: East | K4: Patna | L4: Furniture | M4: Chair | N4: 6 | O4: 6 | P4: 21398.46 | Q4: 0.34 | R4: 75488.55 | S4: 18648.21 | T4: 0.247 | U4: 99.52 | V4: EMI | W4: 4 | X4: FALSE | Y4: Delivered | Z4: Delivered | AA4: 1 | AB4: 1 | AC4: 2024 | AD4: 45627 | AE4: 36-45 | AF4: 31-40% | AG4: =IF(N4=999,"Exclude","Include") -> Include | AH4: =IF(Z4="Returned",1,0) -> 0 | AI4: =IF(OR(Z4="Delivered",Z4="Returned"),1,0) -> 1 | AJ4: =IF(Z4="Cancelled",1,0) -> 0 | AK4: =1 -> 1
A5: ORD-04195 | B5: 45654 | C5: 45654 | D5: CUST13220 | E5: Ritu Gupta | F5: 36 | G5: 36 | H5: Other | I5: Other | J5: East | K5: Bhubaneswar | L5: Furniture | M5: Desk | N5: 9 | O5: 9 | P5: 21875.15 | Q5: 0.01 | R5: 161990.01 | S5: 51700.42 | T5: 0.319 | U5: 87.08 | V5: Credit Card | W5: 4 | X5: FALSE | Y5: Delivered | Z5: Delivered | AA5: 10 | AB5: 10 | AC5: 2024 | AD5: 45627 | AE5: 36-45 | AF5: 1-10% | AG5: =IF(N5=999,"Exclude","Include") -> Include | AH5: =IF(Z5="Returned",1,0) -> 0 | AI5: =IF(OR(Z5="Delivered",Z5="Returned"),1,0) -> 1 | AJ5: =IF(Z5="Cancelled",1,0) -> 0 | AK5: =1 -> 1
A6: ORD-04196 | B6: 45654 | C6: 45654 | D6: CUST70995 | E6: Rahul Gupta | F6: 40 | G6: 40 | H6: Male | I6: Male | J6: North | K6: Ludhiana | L6: Electronics | M6: Headphones | N6: 5 | O6: 5 | P6: 8516.83 | Q6: 0.34 | R6: 25126 | S6: 3420.94 | T6: 0.136 | U6: 56.78 | V6: UPI | W6: 4 | X6: FALSE | Y6: Delivered | Z6: Delivered | AA6: 4 | AB6: 4 | AC6: 2024 | AD6: 45627 | AE6: 36-45 | AF6: 31-40% | AG6: =IF(N6=999,"Exclude","Include") -> Include | AH6: =IF(Z6="Returned",1,0) -> 0 | AI6: =IF(OR(Z6="Delivered",Z6="Returned"),1,0) -> 1 | AJ6: =IF(Z6="Cancelled",1,0) -> 0 | AK6: =1 -> 1
A7: ORD-04197 | B7: December 28, 2024 | C7: 45654 | D7: CUST98908 | E7: Rohan Sharma | F7: 33 | G7: 33 | H7: Female | I7: Female | J7: West | K7: Mumbai | L7: Groceries | M7: Sugar | N7: 1 | O7: 1 | P7: 51.21 | Q7: 0.14 | R7: 42.95 | S7: 2.98 | T7: 0.069 | U7: 49.87 | V7: EMI | W7: 4 | X7: FALSE | Y7: Pending | Z7: Pending | AA7: 8 | AB7: 8 | AC7: 2024 | AD7: 45627 | AE7: 26-35 | AF7: 11-20% | AG7: =IF(N7=999,"Exclude","Include") -> Include | AH7: =IF(Z7="Returned",1,0) -> 0 | AI7: =IF(OR(Z7="Delivered",Z7="Returned"),1,0) -> 0 | AJ7: =IF(Z7="Cancelled",1,0) -> 0 | AK7: =1 -> 1
A8: ORD-04193 | B8: 45654 | C8: 45654 | D8: CUST18192 | E8: Nikhil Bose | F8: 25 | G8: 25 | H8: F | I8: Female | J8: East | K8: Patna | L8: Beauty | M8: Perfume | N8: 5 | O8: 5 | P8: 724.63 | Q8: 0.1 | R8: 3163.89 | S8: 1918.69 | T8: 0.606 | U8: 48.49 | V8: Credit Card | W8: 5 | X8: FALSE | Y8: Delivered | Z8: Delivered | AA8: 6 | AB8: 6 | AC8: 2024 | AD8: 45627 | AE8: 18-25 | AF8: 1-10% | AG8: =IF(N8=999,"Exclude","Include") -> Include | AH8: =IF(Z8="Returned",1,0) -> 0 | AI8: =IF(OR(Z8="Delivered",Z8="Returned"),1,0) -> 1 | AJ8: =IF(Z8="Cancelled",1,0) -> 0 | AK8: =1 -> 1
A9: ORD-04194 | B9: 45654 | C9: 45654 | D9: CUST18508 | E9: Sunita Sharma | F9: 56 | G9: 56 | H9: Male | I9: Male | J9: North | K9: Ludhiana | L9: Books | M9: Biography | N9: 2 | O9: 2 | P9: 709.51 | Q9: 0.08 | R9: 1228.87 | S9: 481.53 | T9: 0.392 | U9: 18.48 | V9: Net Banking | W9: 5 | X9: FALSE | Y9: Cancelled | Z9: Cancelled | AA9: 5 | AB9: 5 | AC9: 2024 | AD9: 45627 | AE9: 46-60 | AF9: 1-10% | AG9: =IF(N9=999,"Exclude","Include") -> Include | AH9: =IF(Z9="Returned",1,0) -> 0 | AI9: =IF(OR(Z9="Delivered",Z9="Returned"),1,0) -> 0 | AJ9: =IF(Z9="Cancelled",1,0) -> 1 | AK9: =1 -> 1
A10: ORD-04192 | B10: 45653 | C10: 45653 | D10: CUST70453 | E10: Shreya Shah | F10: 33 | G10: 33 | H10: m | I10: Male | J10: North | K10: Amritsar | L10: Books | M10: Fiction Novel | P10: 616.57 | Q10: 0.36 | R10: 344.18 | S10: 145.51 | T10: 0.423 | U10: 35.22 | V10: UPI | W10: 4 | X10: FALSE | Y10: Pending | Z10: Pending | AC10: 2024 | AD10: 45627 | AE10: 26-35 | AF10: 31-40% | AG10: =IF(N10=999,"Exclude","Include") -> Include | AH10: =IF(Z10="Returned",1,0) -> 0 | AI10: =IF(OR(Z10="Delivered",Z10="Returned"),1,0) -> 0 | AJ10: =IF(Z10="Cancelled",1,0) -> 0 | AK10: =1 -> 1
A11: ORD-04190 | B11: 45652 | C11: 45652 | D11: CUST01943 | E11: Amit Reddy | F11: 21 | G11: 21 | H11: Other | I11: Other | J11: North | K11: Ludhiana | L11: Sports | M11: Cricket Bat | N11: 6 | O11: 6 | P11: 5492.54 | Q11: 0.09 | R11: 25243.43 | S11: 6104.49 | T11: 0.242 | U11: 71.5 | V11: EMI | W11: 5 | X11: FALSE | Y11: Delivered | Z11: Delivered | AA11: 1 | AB11: 1 | AC11: 2024 | AD11: 45627 | AE11: 18-25 | AF11: 1-10% | AG11: =IF(N11=999,"Exclude","Include") -> Include | AH11: =IF(Z11="Returned",1,0) -> 0 | AI11: =IF(OR(Z11="Delivered",Z11="Returned"),1,0) -> 1 | AJ11: =IF(Z11="Cancelled",1,0) -> 0 | AK11: =1 -> 1
A12: ORD-04188 | B12: 45652 | C12: 45652 | D12: CUST03222 | E12: Pooja Bhat | H12: Other | I12: Other | J12: Central | K12: Bhopal | L12: Furniture | M12: Chair | N12: 10 | O12: 10 | P12: 21965.61 | Q12: 0.25 | R12: 142471.68 | S12: 51299.09 | T12: 0.36 | U12: 54.26 | V12: Net Banking | W12: 1 | X12: TRUE | Y12: Returned | Z12: Returned | AA12: 10 | AB12: 10 | AC12: 2024 | AD12: 45627 | AE12: Unknown | AF12: 21-30% | AG12: =IF(N12=999,"Exclude","Include") -> Include | AH12: =IF(Z12="Returned",1,0) -> 1 | AI12: =IF(OR(Z12="Delivered",Z12="Returned"),1,0) -> 1 | AJ12: =IF(Z12="Cancelled",1,0) -> 0 | AK12: =1 -> 1
A13: ORD-04191 | B13: 45652 | C13: 45652 | D13: CUST42768 | E13: Nisha Singh | F13: 4 | G13: 4 | H13: Female | I13: Female | J13: West | K13: Surat | L13: Sports | M13: Cycle | N13: 8 | O13: 8 | P13: 1646.28 | Q13: 0.25 | R13: 7889.98 | S13: 1643.93 | T13: 0.208 | U13: 58.56 | V13: Cash on Delivery | W13: 4 | X13: FALSE | Y13: Delivered | Z13: Delivered | AA13: 10 | AB13: 10 | AC13: 2024 | AD13: 45627 | AE13: <18 | AF13: 21-30% | AG13: =IF(N13=999,"Exclude","Include") -> Include | AH13: =IF(Z13="Returned",1,0) -> 0 | AI13: =IF(OR(Z13="Delivered",Z13="Returned"),1,0) -> 1 | AJ13: =IF(Z13="Cancelled",1,0) -> 0 | AK13: =1 -> 1
A14: ORD-04189 | B14: 45652 | C14: 45652 | D14: CUST28178 | E14: Sanjay Rao | F14: 32 | G14: 32 | H14: Other | I14: Other | J14: West | K14: Mumbai | L14: Electronics | M14: Smartwatch | N14: 4 | O14: 4 | P14: 64608.94 | Q14: 0.17 | R14: 191352.59 | S14: 27372.68 | T14: 0.143 | U14: 79.41 | V14: Credit Card | W14: 4 | X14: TRUE | Y14: Returned | Z14: Returned | AA14: 5 | AB14: 5 | AC14: 2024 | AD14: 45627 | AE14: 26-35 | AF14: 11-20% | AG14: =IF(N14=999,"Exclude","Include") -> Include | AH14: =IF(Z14="Returned",1,0) -> 1 | AI14: =IF(OR(Z14="Delivered",Z14="Returned"),1,0) -> 1 | AJ14: =IF(Z14="Cancelled",1,0) -> 0 | AK14: =1 -> 1
A15: ORD-04187 | B15: 45651 | C15: 45651 | D15: CUST58320 | E15: Pooja Sharma | H15: Other | I15: Other | J15: West | K15: Ahmedabad | L15: Furniture | M15: Sofa | N15: 8 | O15: 8 | P15: 14656.38 | Q15: 0.05 | R15: 100424.49 | S15: 22861.06 | T15: 0.228 | U15: 54.81 | V15: Debit Card | W15: 1 | X15: FALSE | Y15: Delivered | Z15: Delivered | AA15: 6 | AB15: 6 | AC15: 2024 | AD15: 45627 | AE15: Unknown | AF15: 1-10% | AG15: =IF(N15=999,"Exclude","Include") -> Include | AH15: =IF(Z15="Returned",1,0) -> 0 | AI15: =IF(OR(Z15="Delivered",Z15="Returned"),1,0) -> 1 | AJ15: =IF(Z15="Cancelled",1,0) -> 0 | AK15: =1 -> 1
A16: ORD-04186 | B16: 45651 | C16: 45651 | D16: CUST56795 | E16: Meera Das | F16: 26 | G16: 26 | H16: Other | I16: Other | J16: North | K16: Amritsar | L16: Sports | M16: Tennis Racket | N16: 1 | O16: 1 | P16: 5533.14 | Q16: 0.17 | R16: 4162.69 | S16: 628.33 | T16: 0.151 | U16: 62.44 | V16: EMI | W16: 4 | X16: FALSE | Y16: Cancelled | Z16: Cancelled | AA16: 6 | AB16: 6 | AC16: 2024 | AD16: 45627 | AE16: 26-35 | AF16: 11-20% | AG16: =IF(N16=999,"Exclude","Include") -> Include | AH16: =IF(Z16="Returned",1,0) -> 0 | AI16: =IF(OR(Z16="Delivered",Z16="Returned"),1,0) -> 0 | AJ16: =IF(Z16="Cancelled",1,0) -> 1 | AK16: =1 -> 1
A17: ORD-04185 | B17: 45651 | C17: 45651 | D17: CUST09877 | E17: Nisha Mehta | F17: 11 | G17: 11 | H17: Male | I17: Male | J17: South | K17: Bangalore | L17: Clothing | M17: Kurta | N17: 6 | O17: 6 | P17: 914.9 | Q17: 0.29 | R17: 3583.35 | S17: 1511.38 | T17: 0.422 | U17: 91.61 | V17: Credit Card | W17: 5 | X17: FALSE | Y17: Shipped | Z17: Shipped | AA17: 6 | AB17: 6 | AC17: 2024 | AD17: 45627 | AE17: <18 | AF17: 21-30% | AG17: =IF(N17=999,"Exclude","Include") -> Include | AH17: =IF(Z17="Returned",1,0) -> 0 | AI17: =IF(OR(Z17="Delivered",Z17="Returned"),1,0) -> 0 | AJ17: =IF(Z17="Cancelled",1,0) -> 0 | AK17: =1 -> 1
A18: ORD-04182 | B18: 45650 | C18: 45650 | D18: CUST64358 | E18: Deepa Chatterjee | F18: 38 | G18: 38 | H18: Other | I18: Other | J18: North | K18: Ludhiana | L18: Groceries | M18: Flour | N18: 9 | O18: 9 | P18: 65.35 | Q18: 0 | R18: 550.67 | S18: 52.12 | T18: 0.095 | U18: 35.68 | V18: Net Banking | W18: 5 | X18: FALSE | Y18: Delivered | Z18: Delivered | AC18: 2024 | AD18: 45627 | AE18: 36-45 | AF18: 0 | AG18: =IF(N18=999,"Exclude","Include") -> Include | AH18: =IF(Z18="Returned",1,0) -> 0 | AI18: =IF(OR(Z18="Delivered",Z18="Returned"),1,0) -> 1 | AJ18: =IF(Z18="Cancelled",1,0) -> 0 | AK18: =1 -> 1
A19: ORD-04183 | B19: 45650 | C19: 45650 | D19: CUST82683 | E19: Kavya Patel | F19: 60 | G19: 60 | H19: Female | I19: Female | J19: Central | K19: Indore | L19: Books | M19: Biography | N19: 1 | O19: 1 | P19: 1309.19 | Q19: 0.23 | R19: 976.81 | S19: 529.27 | T19: 0.542 | U19: 64.44 | V19: Debit Card | W19: 2 | X19: FALSE | Y19: Delivered | Z19: Delivered | AA19: 7 | AB19: 7 | AC19: 2024 | AD19: 45627 | AE19: 46-60 | AF19: 21-30% | AG19: =IF(N19=999,"Exclude","Include") -> Include | AH19: =IF(Z19="Returned",1,0) -> 0 | AI19: =IF(OR(Z19="Delivered",Z19="Returned"),1,0) -> 1 | AJ19: =IF(Z19="Cancelled",1,0) -> 0 | AK19: =1 -> 1
A20: ORD-04184 | B20: December 24, 2024 | C20: 45650 | D20: CUST57246 | E20: Shreya Patel | F20: 34 | G20: 34 | H20: m | I20: Male | J20: East | K20: Guwahati | L20: Furniture | M20: Chair | N20: 9 | O20: 9 | P20: 17949.6 | Q20: 0.08 | R20: 129636.87 | S20: 41301.73 | T20: 0.319 | U20: 79.91 | V20: UPI | W20: 5 | X20: FALSE | Y20: Delivered | Z20: Delivered | AA20: 3 | AB20: 3 | AC20: 2024 | AD20: 45627 | AE20: 26-35 | AF20: 1-10% | AG20: =IF(N20=999,"Exclude","Include") -> Include | AH20: =IF(Z20="Returned",1,0) -> 0 | AI20: =IF(OR(Z20="Delivered",Z20="Returned"),1,0) -> 1 | AJ20: =IF(Z20="Cancelled",1,0) -> 0 | AK20: =1 -> 1
A21: ORD-04181 | B21: 45649 | C21: 45649 | D21: CUST34843 | E21: Rohan Chatterjee | F21: 5 | G21: 5 | H21: Male | I21: Male | J21: South | K21: Bangalore | L21: Beauty | M21: Sunscreen | N21: 4 | O21: 4 | P21: 270.17 | Q21: 0.27 | R21: 766.64 | S21: 297.01 | T21: 0.387 | U21: 54.45 | V21: UPI | W21: 2 | X21: FALSE | Y21: Pending | Z21: Pending | AA21: 3 | AB21: 3 | AC21: 2024 | AD21: 45627 | AE21: <18 | AF21: 21-30% | AG21: =IF(N21=999,"Exclude","Include") -> Include | AH21: =IF(Z21="Returned",1,0) -> 0 | AI21: =IF(OR(Z21="Delivered",Z21="Returned"),1,0) -> 0 | AJ21: =IF(Z21="Cancelled",1,0) -> 0 | AK21: =1 -> 1
A22: ORD-04178 | B22: 45648 | C22: 45648 | D22: CUST11016 | E22: Amit Verma | F22: 53 | G22: 53 | H22: Male | I22: Male | J22: West | K22: Mumbai | L22: Beauty | M22: Shampoo | N22: 3 | O22: 3 | P22: 855.83 | Q22: 0.14 | R22: 2047.13 | S22: 587.72 | T22: 0.287 | U22: 59.05 | V22: Net Banking | W22: 4 | X22: FALSE | Y22: Pending | Z22: Pending | AA22: 6 | AB22: 6 | AC22: 2024 | AD22: 45627 | AE22: 46-60 | AF22: 11-20% | AG22: =IF(N22=999,"Exclude","Include") -> Include | AH22: =IF(Z22="Returned",1,0) -> 0 | AI22: =IF(OR(Z22="Delivered",Z22="Returned"),1,0) -> 0 | AJ22: =IF(Z22="Cancelled",1,0) -> 0 | AK22: =1 -> 1
A23: ORD-04180 | B23: 45648 | C23: 45648 | D23: CUST01003 | E23: Priya Pillai | F23: 28 | G23: 28 | H23: Female | I23: Female | J23: Central | K23: Bhopal | L23: Groceries | M23: Sugar | N23: 10 | O23: 10 | P23: 194.61 | Q23: 0.27 | R23: 1329.87 | S23: 143.25 | T23: 0.108 | U23: 23.86 | V23: EMI | W23: 2 | X23: FALSE | Y23: Delivered | Z23: Delivered | AA23: 5 | AB23: 5 | AC23: 2024 | AD23: 45627 | AE23: 26-35 | AF23: 21-30% | AG23: =IF(N23=999,"Exclude","Include") -> Include | AH23: =IF(Z23="Returned",1,0) -> 0 | AI23: =IF(OR(Z23="Delivered",Z23="Returned"),1,0) -> 1 | AJ23: =IF(Z23="Cancelled",1,0) -> 0 | AK23: =1 -> 1
A24: ORD-04179 | B24: 45648 | C24: 45648 | D24: CUST52695 | E24: Meera Mehta | F24: 47 | G24: 47 | H24: Male | I24: Male | J24: North | K24: Chandigarh | L24: Electronics | M24: Laptop | N24: 10 | O24: 10 | P24: 56887.12 | Q24: 0.33 | R24: 320072.27 | S24: 41433.48 | T24: 0.129 | U24: 58.41 | V24: Net Banking | W24: 1 | X24: FALSE | Y24: Delivered | Z24: Delivered | AA24: 6 | AB24: 6 | AC24: 2024 | AD24: 45627 | AE24: 46-60 | AF24: 31-40% | AG24: =IF(N24=999,"Exclude","Include") -> Include | AH24: =IF(Z24="Returned",1,0) -> 0 | AI24: =IF(OR(Z24="Delivered",Z24="Returned"),1,0) -> 1 | AJ24: =IF(Z24="Cancelled",1,0) -> 0 | AK24: =1 -> 1
A25: ORD-04177 | B25: 45647 | C25: 45647 | D25: CUST44560 | E25: Amit Verma | F25: 49 | G25: 49 | H25: female | I25: Female | J25: South | K25: Bangalore | L25: Sports | M25: Dumbbells | N25: 2 | O25: 2 | P25: 13057.02 | Q25: 0.35 | R25: 14206.67 | S25: 3578.76 | T25: 0.252 | U25: 69.31 | V25: Credit Card | W25: 5 | X25: FALSE | Y25: Delivered | Z25: Delivered | AA25: 10 | AB25: 10 | AC25: 2024 | AD25: 45627 | AE25: 46-60 | AF25: 31-40% | AG25: =IF(N25=999,"Exclude","Include") -> Include | AH25: =IF(Z25="Returned",1,0) -> 0 | AI25: =IF(OR(Z25="Delivered",Z25="Returned"),1,0) -> 1 | AJ25: =IF(Z25="Cancelled",1,0) -> 0 | AK25: =1 -> 1
A26: ORD-04176 | B26: 45647 | C26: 45647 | D26: CUST37046 | E26: Rohan Bhat | F26: 30 | G26: 30 | H26: Other | I26: Other | J26: West | K26: Surat | L26: Electronics | M26: Headphones | N26: 6 | O26: 6 | P26: 61234.43 | Q26: 0.24 | R26: 268632.52 | S26: 31422.9 | T26: 0.117 | U26: 48.82 | V26: Credit Card | X26: FALSE | Y26: Delivered | Z26: Delivered | AA26: 4 | AB26: 4 | AC26: 2024 | AD26: 45627 | AE26: 26-35 | AF26: 21-30% | AG26: =IF(N26=999,"Exclude","Include") -> Include | AH26: =IF(Z26="Returned",1,0) -> 0 | AI26: =IF(OR(Z26="Delivered",Z26="Returned"),1,0) -> 1 | AJ26: =IF(Z26="Cancelled",1,0) -> 0 | AK26: =1 -> 1
A27: ORD-04175 | B27: 45646 | C27: 45646 | D27: CUST38221 | E27: Pooja Kapoor | F27: 48 | G27: 48 | H27: Other | I27: Other | J27: North | K27: Ludhiana | L27: Beauty | M27: Lipstick | N27: 5 | O27: 5 | P27: 1283.61 | Q27: 0.36 | R27: 3770.64 | S27: 2025.41 | T27: 0.537 | U27: 50.14 | V27: Credit Card | W27: 4 | X27: FALSE | Y27: Delivered | Z27: Delivered | AA27: 8 | AB27: 8 | AC27: 2024 | AD27: 45627 | AE27: 46-60 | AF27: 31-40% | AG27: =IF(N27=999,"Exclude","Include") -> Include | AH27: =IF(Z27="Returned",1,0) -> 0 | AI27: =IF(OR(Z27="Delivered",Z27="Returned"),1,0) -> 1 | AJ27: =IF(Z27="Cancelled",1,0) -> 0 | AK27: =1 -> 1
A28: ORD-04174 | B28: 45645 | C28: 45645 | D28: CUST60428 | E28: Deepa Pillai | F28: 17 | G28: 17 | H28: Other | I28: Other | J28: South | K28: Kochi | L28: Furniture | M28: Bed Frame | N28: 5 | O28: 5 | P28: 22094.81 | Q28: 0.05 | R28: 95653.07 | S28: 32975.78 | T28: 0.345 | U28: 89.18 | V28: Net Banking | W28: 3 | X28: FALSE | Y28: Delivered | Z28: Delivered | AA28: 3 | AB28: 3 | AC28: 2024 | AD28: 45627 | AE28: <18 | AF28: 1-10% | AG28: =IF(N28=999,"Exclude","Include") -> Include | AH28: =IF(Z28="Returned",1,0) -> 0 | AI28: =IF(OR(Z28="Delivered",Z28="Returned"),1,0) -> 1 | AJ28: =IF(Z28="Cancelled",1,0) -> 0 | AK28: =1 -> 1
A29: ORD-04171 | B29: 45643 | C29: 45643 | D29: CUST15084 | E29: Nikhil Mishra | F29: 43 | G29: 43 | H29: Male | I29: Male | J29: South | K29: Kochi | L29: Clothing | M29: Jacket | N29: 5 | O29: 5 | P29: 3006.52 | Q29: 0.12 | R29: 10622.32 | S29: 4837.79 | T29: 0.455 | U29: 75.97 | V29: Credit Card | W29: 1 | X29: FALSE | Y29: Delivered | Z29: Delivered | AA29: 5 | AB29: 5 | AC29: 2024 | AD29: 45627 | AE29: 36-45 | AF29: 11-20% | AG29: =IF(N29=999,"Exclude","Include") -> Include | AH29: =IF(Z29="Returned",1,0) -> 0 | AI29: =IF(OR(Z29="Delivered",Z29="Returned"),1,0) -> 1 | AJ29: =IF(Z29="Cancelled",1,0) -> 0 | AK29: =1 -> 1
A30: ORD-04172 | B30: 45643 | C30: 45643 | D30: CUST07872 | E30: Meera Rao | F30: 32 | G30: 32 | H30: m | I30: Male | J30: North | K30: Ludhiana | L30: Beauty | M30: Lipstick | N30: 5 | O30: 5 | P30: 2144.13 | Q30: 0.1 | R30: 9449.37 | S30: 4541.29 | T30: 0.481 | U30: 19.04 | V30: Debit Card | X30: FALSE | Y30: Delivered | Z30: Delivered | AA30: 5 | AB30: 5 | AC30: 2024 | AD30: 45627 | AE30: 26-35 | AF30: 1-10% | AG30: =IF(N30=999,"Exclude","Include") -> Include | AH30: =IF(Z30="Returned",1,0) -> 0 | AI30: =IF(OR(Z30="Delivered",Z30="Returned"),1,0) -> 1 | AJ30: =IF(Z30="Cancelled",1,0) -> 0 | AK30: =1 -> 1
A31: ORD-04173 | B31: 45643 | C31: 45643 | D31: CUST95025 | E31: Aditya Kapoor | F31: 18 | G31: 18 | H31: Female | I31: Female | J31: North | K31: Ludhiana | L31: Furniture | M31: Sofa | N31: 6 | O31: 6 | P31: 29938.75 | Q31: 0.17 | R31: 139138.9 | S31: 44922.96 | T31: 0.323 | U31: 34.46 | V31: Cash on Delivery | W31: 1 | X31: FALSE | Y31: Delivered | Z31: Delivered | AA31: 9 | AB31: 9 | AC31: 2024 | AD31: 45627 | AE31: 18-25 | AF31: 11-20% | AG31: =IF(N31=999,"Exclude","Include") -> Include | AH31: =IF(Z31="Returned",1,0) -> 0 | AI31: =IF(OR(Z31="Delivered",Z31="Returned"),1,0) -> 1 | AJ31: =IF(Z31="Cancelled",1,0) -> 0 | AK31: =1 -> 1
A32: ORD-04169 | B32: 45642 | C32: 45642 | D32: CUST68700 | E32: Aditya Mehta | F32: 33 | G32: 33 | H32: Female | I32: Female | J32: South | K32: Bangalore | L32: Sports | M32: Football | N32: 9 | O32: 9 | P32: 7976.73 | R32: 57905.39 | S32: 13844.42 | T32: 0.239 | U32: 69.85 | V32: EMI | W32: 1 | X32: FALSE | Y32: Delivered | Z32: Delivered | AA32: 8 | AB32: 8 | AC32: 2024 | AD32: 45627 | AE32: 26-35 | AF32: No data | AG32: =IF(N32=999,"Exclude","Include") -> Include | AH32: =IF(Z32="Returned",1,0) -> 0 | AI32: =IF(OR(Z32="Delivered",Z32="Returned"),1,0) -> 1 | AJ32: =IF(Z32="Cancelled",1,0) -> 0 | AK32: =1 -> 1
A33: ORD-04170 | B33: 45642 | C33: 45642 | D33: CUST70820 | E33: Nikhil Iyer | F33: 14 | G33: 14 | H33: Male | I33: Male | J33: East | K33: Kolkata | L33: Clothing | M33: Jeans | N33: 4 | O33: 4 | P33: 1999.6 | Q33: 0.4 | R33: 4690.45 | S33: 1146.6 | T33: 0.244 | U33: 66.84 | V33: Net Banking | X33: FALSE | Y33: Delivered | Z33: Delivered | AC33: 2024 | AD33: 45627 | AE33: <18 | AF33: 31-40% | AG33: =IF(N33=999,"Exclude","Include") -> Include | AH33: =IF(Z33="Returned",1,0) -> 0 | AI33: =IF(OR(Z33="Delivered",Z33="Returned"),1,0) -> 1 | AJ33: =IF(Z33="Cancelled",1,0) -> 0 | AK33: =1 -> 1
A34: ORD-04167 | B34: 45641 | C34: 45641 | D34: CUST06213 | E34: Kavya Patel | F34: 29 | G34: 29 | H34: Other | I34: Other | J34: East | K34: Bhubaneswar | L34: Furniture | M34: Bed Frame | N34: 9 | O34: 9 | P34: 26558.96 | Q34: 0.12 | R34: 191023.49 | S34: 41485.81 | T34: 0.217 | U34: 110.49 | V34: Net Banking | W34: 3 | X34: TRUE | Y34: Returned | Z34: Returned | AA34: 6 | AB34: 6 | AC34: 2024 | AD34: 45627 | AE34: 26-35 | AF34: 11-20% | AG34: =IF(N34=999,"Exclude","Include") -> Include | AH34: =IF(Z34="Returned",1,0) -> 1 | AI34: =IF(OR(Z34="Delivered",Z34="Returned"),1,0) -> 1 | AJ34: =IF(Z34="Cancelled",1,0) -> 0 | AK34: =1 -> 1
A35: ORD-04165 | B35: 45641 | C35: 45641 | D35: CUST82149 | E35: Nisha Verma | F35: 38 | G35: 38 | H35: MALE | I35: Male | J35: East | K35: Bhubaneswar | L35: Electronics | M35: Smartwatch | N35: 4 | O35: 4 | P35: 62134.64 | Q35: 0.31 | R35: 151708.44 | S35: 17375.7 | T35: 0.115 | U35: 66.2 | V35: Net Banking | X35: FALSE | Y35: Delivered | Z35: Delivered | AA35: 1 | AB35: 1 | AC35: 2024 | AD35: 45627 | AE35: 36-45 | AF35: 31-40% | AG35: =IF(N35=999,"Exclude","Include") -> Include | AH35: =IF(Z35="Returned",1,0) -> 0 | AI35: =IF(OR(Z35="Delivered",Z35="Returned"),1,0) -> 1 | AJ35: =IF(Z35="Cancelled",1,0) -> 0 | AK35: =1 -> 1
A36: ORD-04168 | B36: 45641 | C36: 45641 | D36: CUST39751 | E36: Meera Iyer | H36: Female | I36: Female | J36: West | K36: Ahmedabad | L36: Sports | M36: Tennis Racket | N36: 2 | O36: 2 | P36: 10972.39 | Q36: 0.3 | R36: 11894.53 | S36: 2981.58 | T36: 0.251 | U36: 43.93 | V36: EMI | W36: 2 | X36: FALSE | Y36: Delivered | Z36: Delivered | AA36: 10 | AB36: 10 | AC36: 2024 | AD36: 45627 | AE36: Unknown | AF36: 21-30% | AG36: =IF(N36=999,"Exclude","Include") -> Include | AH36: =IF(Z36="Returned",1,0) -> 0 | AI36: =IF(OR(Z36="Delivered",Z36="Returned"),1,0) -> 1 | AJ36: =IF(Z36="Cancelled",1,0) -> 0 | AK36: =1 -> 1
A37: ORD-04166 | B37: 45641 | C37: 45641 | D37: CUST73620 | E37: Rohan Reddy | F37: 18 | G37: 18 | H37: Female | I37: Female | J37: South | K37: Bangalore | L37: Clothing | M37: T-Shirt | N37: 6 | O37: 6 | P37: 841.47 | Q37: 0.12 | R37: 4321.42 | S37: 1728.55 | T37: 0.4 | U37: 70.62 | V37: UPI | W37: 1 | X37: FALSE | Y37: Delivered | Z37: Delivered | AA37: 2 | AB37: 2 | AC37: 2024 | AD37: 45627 | AE37: 18-25 | AF37: 11-20% | AG37: =IF(N37=999,"Exclude","Include") -> Include | AH37: =IF(Z37="Returned",1,0) -> 0 | AI37: =IF(OR(Z37="Delivered",Z37="Returned"),1,0) -> 1 | AJ37: =IF(Z37="Cancelled",1,0) -> 0 | AK37: =1 -> 1
A38: ORD-04164 | B38: 45640 | C38: 45640 | D38: CUST96903 | E38: Deepa Kapoor | F38: 46 | G38: 46 | H38: Other | I38: Other | J38: North | K38: Amritsar | L38: Furniture | M38: Chair | N38: 1 | O38: 1 | P38: 9449.94 | Q38: 0.15 | R38: 7223.61 | S38: 2224.51 | T38: 0.308 | U38: 32.57 | V38: UPI | W38: 1 | X38: TRUE | Y38: Returned | Z38: Returned | AA38: 2 | AB38: 2 | AC38: 2024 | AD38: 45627 | AE38: 46-60 | AF38: 11-20% | AG38: =IF(N38=999,"Exclude","Include") -> Include | AH38: =IF(Z38="Returned",1,0) -> 1 | AI38: =IF(OR(Z38="Delivered",Z38="Returned"),1,0) -> 1 | AJ38: =IF(Z38="Cancelled",1,0) -> 0 | AK38: =1 -> 1
A39: ORD-04160 | B39: 45637 | C39: 45637 | D39: CUST91116 | E39: Rohan Patel | F39: 36 | G39: 36 | H39: Male | I39: Male | J39: South | K39: Hyderabad | L39: Books | M39: Biography | N39: 7 | O39: 7 | P39: 609.79 | Q39: 0.25 | R39: 2905.61 | S39: 1079.08 | T39: 0.371 | U39: 68.86 | V39: UPI | W39: 3 | X39: FALSE | Y39: Delivered | Z39: Delivered | AA39: 7 | AB39: 7 | AC39: 2024 | AD39: 45627 | AE39: 36-45 | AF39: 21-30% | AG39: =IF(N39=999,"Exclude","Include") -> Include | AH39: =IF(Z39="Returned",1,0) -> 0 | AI39: =IF(OR(Z39="Delivered",Z39="Returned"),1,0) -> 1 | AJ39: =IF(Z39="Cancelled",1,0) -> 0 | AK39: =1 -> 1
A40: ORD-04161 | B40: 45637 | C40: 45637 | D40: CUST28262 | E40: Aarav Patel | F40: 22 | G40: 22 | H40: Male | I40: Male | J40: South | K40: Chennai | L40: Groceries | M40: Rice (5kg) | N40: 3 | O40: 3 | P40: 55.73 | Q40: 0.25 | R40: 132.26 | S40: 9.16 | T40: 0.069 | U40: 67.07 | V40: Credit Card | W40: 4 | X40: TRUE | Y40: Returned | Z40: Returned | AA40: 9 | AB40: 9 | AC40: 2024 | AD40: 45627 | AE40: 18-25 | AF40: 21-30% | AG40: =IF(N40=999,"Exclude","Include") -> Include | AH40: =IF(Z40="Returned",1,0) -> 1 | AI40: =IF(OR(Z40="Delivered",Z40="Returned"),1,0) -> 1 | AJ40: =IF(Z40="Cancelled",1,0) -> 0 | AK40: =1 -> 1
...

Sheet Per Tahun
A1: order_status_clean | B1: Delivered
A2: sales_flag | B2: Include
A4: Row Labels | B4: Sum of sales_amount | C4: Sum of profit
A5: 2020 | B5: 24493418 | C5: 4582796.9
A6: 2021 | B6: 29858426 | C6: 5408425.1
A7: 2022 | B7: 32976549 | C7: 6295256.3
A8: 2023 | B8: 32599571 | C8: 5960575.6
A9: 2024 | B9: 33587242 | C9: 6462756.1
A10: Grand Total | B10: 153515205 | C10: 28709810

Sheet Bulanan
A1: order_status_clean | B1: Delivered
A2: sales_flag | B2: Include
A4: Row Labels | B4: Sum of sales_amount
A5: 43831 | B5: 944705.47
A6: 43862 | B6: 1316719.4
A7: 43891 | B7: 1556181
A8: 43922 | B8: 1812229.5
A9: 43952 | B9: 4415841.7
A10: 43983 | B10: 2266182.7
A11: 44013 | B11: 3707588.1
A12: 44044 | B12: 1605204.2
A13: 44075 | B13: 1770257.8
A14: 44105 | B14: 2057622.4
A15: 44136 | B15: 987267.89
A16: 44166 | B16: 2053617.7
... A64: 45627 | B64: 2104057.4
A65: Grand Total | B65: 1.5351521e+08

Sheet Kategori
A1: order_status_clean | B1: Delivered
A2: sales_flag | B2: Include
A4: Row Labels | B4: Penjualan | C4: Margin %
A5: Electronics | B5: 88979113 | C5: 0.11937182
A6: Furniture | B6: 39662721 | C6: 0.28373867
A7: Sports | B7: 16076064 | C7: 0.22066753
A8: Clothing | B8: 4252225.8 | C8: 0.35501945
A9: Beauty | B9: 2551914.5 | C9: 0.44966841
A10: Books | B10: 1476232.2 | C10: 0.39900197
A11: Groceries | B11: 516935.54 | C11: 0.078811335
A12: Grand Total | B12: 1.535152e+08 | C12: 0.18701607

Sheet Kategori x Tahun
A1: order_status_clean | B1: Delivered
A2: sales_flag | B2: Include
A4: Sum of sales_amount | B4: Column Labels
A5: Row Labels | B5: 2020 | C5: 2021 | D5: 2022 | E5: 2023 | F5: 2024 | G5: Grand Total
A6: Beauty | B6: 440853.68 | C6: 446379.01 | D6: 506039.04 | E6: 543789.31 | F6: 614853.48 | G6: 2551914.5
A7: Books | B7: 241989.7 | C7: 287227.9 | D7: 274654.03 | E7: 327406.2 | F7: 344954.42 | G7: 1476232.2
A8: Clothing | B8: 585207.35 | C8: 828007.12 | D8: 899934.98 | E8: 934709.56 | F8: 1004366.8 | G8: 4252225.8
A9: Electronics | B9: 13708200 | C9: 18349261 | D9: 18407416 | E9: 19158618 | F9: 19355617 | G9: 88979113
A10: Furniture | B10: 6133848.8 | C10: 6323745 | D10: 9627694.3 | E10: 7703882.3 | F10: 9873550.1 | G10: 39662721
A11: Groceries | B11: 95456.37 | C11: 91095.93 | D11: 108438.54 | E11: 102897.8 | F11: 119046.9 | G11: 516935.54
A12: Sports | B12: 3287861.6 | C12: 3532709.5 | D12: 3152372.1 | E12: 3828267.4 | F12: 2274853.2 | G12: 16076064
A13: Grand Total | B13: 24493418 | C13: 29858426 | D13: 32976549 | E13: 32599571 | F13: 33587242 | G13: 153515205

Sheet Sports
A1: product_category | B1: Sports
A2: order_status_clean | B2: Delivered
A3: sales_flag | B3: Include
A5: Row Labels | B5: Count of order_id | C5: Sum of sales_amount | D5: Average of sales_amount2
A6: 2020 | B6: 85 | C6: 3287861.6 | D6: 38680.725
A7: 2021 | B7: 84 | C7: 3532709.5 | D7: 42056.066
A8: 2022 | B8: 84 | C8: 3152372.1 | D8: 37528.24
A9: 2023 | B9: 91 | C9: 3828267.4 | D9: 42068.872
A10: 2024 | B10: 68 | C10: 2274853.2 | D10: 33453.724
A11: Grand Total | B11: 412 | C11: 16076064 | D11: 39019.572

Sheet Penjualan Per Tahun (Sports)
A1: order_status_clean | B1: Delivered
A2: product_category | B2: Sports
A3: sales_flag | B3: Include
A5: Sum of sales_amount | B5: Column Labels
A6: Row Labels | B6: 2020 | C6: 2021 | D6: 2022 | E6: 2023 | F6: 2024 | G6: Grand Total
A7: Cricket Bat | B7: 420738.08 | C7: 1068777.2 | D7: 552583.9 | E7: 306592.45 | F7: 433244.51 | G7: 2781936.1
A8: Cycle | B8: 497335.69 | C8: 461825.95 | D8: 244610.9 | E8: 340657.82 | F8: 189121.44 | G8: 1733551.8
A9: Dumbbells | B9: 550713.17 | C9: 335167.35 | D9: 564971.2 | E9: 1209187.6 | F9: 557920.86 | G9: 3217960.2
A10: Football | B10: 721875.42 | C10: 642420.2 | D10: 650884.07 | E10: 569824.86 | F10: 339225.46 | G10: 2924230
A11: Tennis Racket | B11: 313153.39 | C11: 461901.48 | D11: 596331.45 | E11: 494079.59 | F11: 274844.05 | G11: 2140310
A12: Yoga Mat | B12: 784045.84 | C12: 562617.39 | D12: 542990.61 | E12: 907925.03 | F12: 480496.92 | G12: 3278075.8
A13: Grand Total | B13: 3287861.6 | C13: 3532709.5 | D13: 3152372.1 | E13: 3828267.4 | F13: 2274853.2 | G13: 16076064

Sheet Diskon
A1: order_status_clean | B1: Delivered
A2: sales_flag | B2: Include
A4: Row Labels | B4: Count of order_id | C4: Sum of sales_amount | D4: Sum of profit | E4: Sum of Margin
A5: 0 | B5: 29 | C5: 3449019.8 | D5: 544219.59 | E5: 0.15778964
A6: 1-10% | B6: 674 | C6: 39612856 | D6: 7450155.4 | E6: 0.18807418
A7: 11-20% | B7: 617 | C7: 38483846 | D7: 7139755.5 | E7: 0.18552604
A8: 21-30% | B8: 659 | C8: 37652690 | D8: 7073482.8 | E8: 0.18786129
A9: 31-40% | B9: 652 | C9: 27540735 | D9: 5071165.9 | E9: 0.18413328
A10: No data | B10: 94 | C10: 6776058.8 | D10: 1431030.8 | E10: 0.21118925
A11: Grand Total | B11: 2725 | C11: 1.5351521e+08 | D11: 28709810 | E11: 0.18701607

Sheet Payment
A1: order_status_clean | B1: Delivered | D1: Payment Methods
A2: sales_flag | B2: Include
A4: Row Labels | B4: Count of order_id
A5: UPI | B5: 496
A6: Credit Card | B6: 467
A7: Cash on Delivery | B7: 451
A8: EMI | B8: 440
A9: Net Banking | B9: 439
A10: Debit Card | B10: 432
A11: Grand Total | B11: 2725

Sheet Top 10
A1: order_status_clean | B1: Delivered
A2: sales_flag | B2: Include
A4: Row Labels | B4: Count of order_id | C4: Sum of sales_amount | D4: Sum of profit | E4: Sum of Margin
A5: Headphones | B5: 75 | C5: 19079423 | D5: 2252649.9 | E5: 0.11806698
A6: Desk | B6: 72 | C6: 7843971.1 | D6: 2185118.7 | E6: 0.27857302
A7: Wardrobe | B7: 64 | C7: 6976125.5 | D7: 2050081.6 | E7: 0.29387109
A8: Laptop | B8: 69 | C8: 17104668 | D8: 1974650.5 | E8: 0.11544513
A9: Sofa | B9: 58 | C9: 6504023.4 | D9: 1931222.1 | E9: 0.2969273
A10: Smartwatch | B10: 65 | C10: 15125842 | D10: 1826935.4 | E10: 0.1207824
A11: Bed Frame | B11: 69 | C11: 6468219.7 | D11: 1809008.1 | E11: 0.27967635
A12: Chair | B12: 59 | C12: 6047917.9 | D12: 1703254.8 | E12: 0.28162664
A13: Camera | B13: 58 | C13: 13998888 | D13: 1640238.2 | E13: 0.11716918
A14: Bookshelf | B14: 64 | C14: 5822463 | D14: 1575162.4 | E14: 0.27053197
A15: Grand Total | B15: 653 | C15: 1.0497154e+08 | D15: 18948322 | E15: 0.18050913

Sheet Bottom 10
A1: order_status_clean | B1: Delivered
A2: sales_flag | B2: Include
A4: Row Labels | B4: Count of order_id | C4: Sum of sales_amount | D4: Sum of profit | E4: Sum of Margin
A5: Rice (5kg) | B5: 63 | C5: 76391.66 | D5: 5784.38 | E5: 0.075720046
A6: Dal (1kg) | B6: 67 | C6: 80765.21 | D6: 6224.34 | E6: 0.077067094
A7: Flour | B7: 61 | C7: 82661.48 | D7: 6477.89 | E7: 0.078366489
A8: Sugar | B8: 58 | C8: 83734.58 | D8: 6642.41 | E8: 0.079326964
A9: Cooking Oil | B9: 64 | C9: 94444.78 | D9: 7330.65 | E9: 0.077618371
A10: Tea | B10: 62 | C10: 98937.83 | D10: 8280.71 | E10: 0.083696095
A11: Cook Book | B11: 52 | C11: 199473.52 | D11: 80105.75 | E11: 0.40158588
A12: Self-Help Book | B12: 62 | C12: 217934.28 | D12: 84257.72 | E12: 0.38661986
A13: Biography | B13: 52 | C13: 225604.18 | D13: 88710.24 | E13: 0.39321186
A14: Fiction Novel | B14: 76 | C14: 243865.5 | D14: 97151.44 | E14: 0.39838124
A15: Grand Total | B15: 617 | C15: 1403813 | D15: 390965.53 | E15: 0.27850257

Sheet Pivot Cancellation
A3: Row Labels | B3: Sum of cancelled | C3: Sum of orders_count | D3: Sum of Cancel Rate
A4: Cash on Delivery | B4: 55 | C4: 703 | D4: 0.078236131
A5: Credit Card | B5: 56 | C5: 721 | D5: 0.077669903
A6: Debit Card | B6: 69 | C6: 683 | D6: 0.10102489
A7: EMI | B7: 56 | C7: 683 | D7: 0.081991215
A8: Net Banking | B8: 52 | C8: 661 | D8: 0.078668684
A9: UPI | B9: 58 | C9: 749 | D9: 0.077436582
A10: (blank) | D10: #DIV/0!
A11: Grand Total | B11: 346 | C11: 4200 | D11: 0.082380952

Sheet Segmen
A1: order_status_clean | B1: Delivered
A2: sales_flag | B2: Include
A4: Row Labels | B4: Count of order_id | C4: Sum of sales_amount | D4: Sum of profit | E4: Sum of margin
A5: <18 | B5: 208 | C5: 12211811 | D5: 2145532 | E5: 0.17569319
A6: 18-25 | B6: 404 | C6: 26708147 | D6: 4727245.4 | E6: 0.17699638
A7: 26-35 | B7: 809 | C7: 42665646 | D7: 8085836.4 | E7: 0.18951633
A8: 36-45 | B8: 722 | C8: 41003329 | D8: 7842620.4 | E8: 0.19126789
A9: 46-60 | B9: 450 | C9: 23439151 | D9: 4647348.3 | E9: 0.19827289
A10: 60+ | B10: 36 | C10: 1322369.9 | D10: 258425.77 | E10: 0.19542623
A11: Unknown | B11: 96 | C11: 6164750.6 | D11: 1002801.8 | E11: 0.16266704
A12: Grand Total | B12: 2725 | C12: 1.5351521e+08 | D12: 28709810 | E12: 0.18701607

Sheet Pivot Kepuasan
A1: order_status_clean | B1: Delivered
A3: Row Labels | B3: Rata-rata Kepuasan | C3: Jumlah Rating
A4: 1 | B4: 3.246696 | C4: 227
A5: 2 | B5: 3.2226721 | C5: 247
A6: 3 | B6: 2.9918033 | C6: 244
A7: 4 | B7: 3.0368852 | C7: 244
A8: 5 | B8: 3.1196581 | C8: 234
A9: 6 | B9: 3.1264822 | C9: 253
A10: 7 | B10: 3.2268908 | C10: 238
A11: 8 | B11: 3.0269231 | C11: 260
A12: 9 | B12: 3.2669323 | C12: 251
A13: 10 | B13: 3.0083333 | C13: 240
A14: (blank) | B14: 3.2923077 | C14: 65
A15: Grand Total | B15: 3.1306432 | C15: 2503

Sheet KPI
A1: order_status_clean | B1: Delivered
A2: sales_flag | B2: Include
A4: Jumlah Order | B4: Total Penjualan | C4: Total Profit | D4: Rata-rata Per Order | E4: Sum of margin | F4: Rata-Rata Kepuasan | G4: Count of order_id
A5: 2725 | B5: 1.5351521e+08 | C5: 28709810 | D5: 56335.855 | E5: 0.18701607 | F5: 3.1301041 | G5: 2725

Sheet Sheet6
A1: order_status_clean | B1: Delivered
A2: sales_flag | B2: Include
A4: Row Labels | B4: Penjualan | C4: Sum of profit | D4: Sum of Margin
A5: Beauty | B5: 2551914.5 | C5: 1147515.4 | D5: 0.44966841
A6: Books | B6: 1476232.2 | C6: 589019.58 | D6: 0.39900197
A7: Clothing | B7: 4252225.8 | C7: 1509622.9 | D7: 0.35501945
A8: Electronics | B8: 88979113 | C8: 10621599 | D8: 0.11937182
A9: Furniture | B9: 39662721 | C9: 11253848 | D9: 0.28373867
A10: Groceries | B10: 516935.54 | C10: 40740.38 | D10: 0.078811335
A11: Sports | B11: 16076064 | C11: 3547465.3 | D11: 0.22066753
A12: Grand Total | B12: 1.535152e+08 | C12: 28709810 | D12: 0.18701607

Sheet Dashboard
G7: Total Penjualan | I7: Total Profit | K7: Margin | M7: Jumlah Order | O7: Rata-Rata Per Oder
G8: =GETPIVOTDATA("Total Penjualan",KPI!$A$4) -> 1.5351521e+08 | I8: =GETPIVOTDATA("Total Profit",KPI!$A$4) -> 28709810 | K8: =GETPIVOTDATA("Sum of margin",KPI!$A$4) -> 0.18701607 | M8: =GETPIVOTDATA("Jumlah Order",KPI!$A$4) -> 2725 | O8: =GETPIVOTDATA("Rata-rata Per Order",KPI!$A$4) -> 56335.855
